Workbook
Name SegmentaciónDeDatos_Año: #N/A
Name SegmentaciónDeDatos_Ingenio: #N/A
Name SegmentaciónDeDatos_Mes: #N/A
Name SegmentaciónDeDatos_Sind_No_sind: #N/A

Sheet Ausentismos
A1: Ingenio | B1: Plantilla | C1: Sind/No sind | D1: Días laborables del mes | E1: Mes | F1: Jornales | G1: FI | H1: PSG | I1: EG | J1: RT | K1: Ausencias | L1: REAL AUSENT. | M1: REAL COMPR. | N1: PLAN AUSENT. | O1: PLAN COMPR. | P1: DIF +/- | Q1: Orden | R1: Año | S1: ID
A2: Huixtla | B2: 175 | C2: No Sindicalizados | D2: 26 | E2: Enero | F2: 4550 | G2: 0 | H2: 0 | I2: 2 | J2: 0 | K2: 2 | L2: 0.00043956044 | M2: 0.99956044 | N2: 0 | O2: 1 | P2: 0.00043956044 | Q2: 1 | R2: 2023 | S2: 44927
A3: Huixtla | B3: 195 | C3: No Sindicalizados | D3: 24 | E3: Febrero | F3: 4680 | G3: 0 | H3: 0 | I3: 23 | J3: 0 | K3: 23 | L3: 0.0049145299 | M3: 0.99508547 | N3: 0 | O3: 1 | P3: 0.0049145299 | Q3: 2 | R3: 2023 | S3: 44958
A4: Huixtla | B4: 195 | C4: No Sindicalizados | D4: 26 | E4: Marzo | F4: 5070 | G4: 0 | H4: 0 | I4: 0 | J4: 5 | K4: 5 | L4: 0.00098619329 | M4: 0.99901381 | N4: 0 | O4: 1 | P4: 0.00098619329 | Q4: 3 | R4: 2023 | S4: 44986
A5: Huixtla | B5: 195 | C5: No Sindicalizados | D5: 25 | E5: Abril | F5: 4875 | G5: 0 | H5: 6 | I5: 0 | J5: 19 | K5: 25 | L5: 0.0051282051 | M5: 0.99487179 | N5: 0 | O5: 1 | P5: 0.0051282051 | Q5: 4 | R5: 2023 | S5: 45017
A6: Huixtla | B6: 195 | C6: No Sindicalizados | D6: 21 | E6: Mayo | F6: 4095 | G6: 0 | H6: 0 | I6: 0 | J6: 36 | K6: 36 | L6: 0.0087912088 | M6: 0.99120879 | N6: 0 | O6: 1 | P6: 0.0087912088 | Q6: 5 | R6: 2023 | S6: 45047
A7: Huixtla | B7: 137 | C7: No Sindicalizados | D7: 22 | E7: Junio | F7: 3014 | G7: 0 | H7: 0 | I7: 10 | J7: 0 | K7: 10 | L7: 0.00331785 | M7: 0.99668215 | N7: 0 | O7: 1 | P7: 0.00331785 | Q7: 6 | R7: 2023 | S7: 45078
A8: Huixtla | B8: 137 | C8: No Sindicalizados | D8: 21 | E8: Julio | F8: 2877 | G8: 0 | H8: 3 | I8: 0 | J8: 0 | K8: 3 | L8: 0.0010427529 | M8: 0.99895725 | N8: 0 | O8: 1 | P8: 0.0010427529 | Q8: 7 | R8: 2023 | S8: 45108
A9: Huixtla | B9: 135 | C9: No Sindicalizados | D9: 23 | E9: Agosto | F9: 3105 | G9: 0 | H9: 0 | I9: 22 | J9: 0 | K9: 22 | L9: 0.0070853462 | M9: 0.99291465 | N9: 0 | O9: 1 | P9: 0.0070853462 | Q9: 8 | R9: 2023 | S9: 45139
A10: Huixtla | B10: 137 | C10: No Sindicalizados | D10: 21 | E10: Septiembre | F10: 2877 | G10: 1 | H10: 0 | I10: 12 | J10: 0 | K10: 13 | L10: 0.0045185958 | M10: 0.9954814 | N10: 0 | O10: 1 | P10: 0.0045185958 | Q10: 9 | R10: 2023 | S10: 45170
A11: Huixtla | B11: 143 | C11: No Sindicalizados | D11: 22 | E11: Octubre | F11: 3146 | G11: 0 | H11: 5 | I11: 0 | J11: 0 | K11: 5 | L11: 0.0015893198 | M11: 0.99841068 | N11: 0 | O11: 1 | P11: 0.0015893198 | Q11: 10 | R11: 2023 | S11: 45200
A12: Huixtla | B12: 192 | C12: No Sindicalizados | D12: 14 | E12: Noviembre | F12: 2688 | G12: 0 | H12: 2 | I12: 0 | J12: 0 | K12: 2 | L12: 0.00074404762 | M12: 0.99925595 | N12: 0 | O12: 1 | P12: 0.00074404762 | Q12: 11 | R12: 2023 | S12: 45231
A13: Huixtla | B13: 194 | C13: No Sindicalizados | D13: 25 | E13: Diciembre | F13: 4850 | G13: 0 | H13: 0 | I13: 11 | J13: 0 | K13: 11 | L13: 0.0022680412 | M13: 0.99773196 | N13: 0 | O13: 1 | P13: 0.0022680412 | Q13: 12 | R13: 2023 | S13: 45261
... A81: Huixtla | B81: 218 | C81: No Sindicalizados | D81: 26 | E81: Abril | F81: 5668 | G81: 0 | H81: 0 | I81: 75 | J81: 0 | K81: 75 | L81: 0.013232181 | M81: 0.98676782 | N81: 0.1026 | O81: 0.8974 | P81: -0.089367819 | Q81: 4 | R81: 2026 | S81: 46113
A82: Huixtla | C82: Sindicalizados (Perm. Y Temp) | E82: Mayo | N82: 0.0957 | O82: 0.9043 | Q82: 5 | R82: 2026 | S82: 46143
A83: Huixtla | C83: No Sindicalizados | E83: Mayo | N83: 0.0957 | O83: 0.9043 | Q83: 5 | R83: 2026 | S83: 46143
A84: Huixtla | C84: Sindicalizados (Perm. Y Temp) | E84: Junio | N84: 0.1131 | O84: 0.8869 | Q84: 6 | R84: 2026 | S84: 46174
A85: Huixtla | C85: No Sindicalizados | E85: Junio | N85: 0.1131 | O85: 0.8869 | Q85: 6 | R85: 2026 | S85: 46174
A86: Huixtla | C86: Sindicalizados (Perm. Y Temp) | E86: Julio | N86: 0.0883 | O86: 0.9117 | Q86: 7 | R86: 2026 | S86: 46204
A87: Huixtla | C87: No Sindicalizados | E87: Julio | N87: 0.0883 | O87: 0.9117 | Q87: 7 | R87: 2026 | S87: 46204
A88: Huixtla | C88: Sindicalizados (Perm. Y Temp) | E88: Agosto | N88: 0.078 | O88: 0.922 | Q88: 8 | R88: 2026 | S88: 46235
A89: Huixtla | C89: No Sindicalizados | E89: Agosto | N89: 0.078 | O89: 0.922 | Q89: 8 | R89: 2026 | S89: 46235
A90: Huixtla | C90: Sindicalizados (Perm. Y Temp) | E90: Septiembre | N90: 0.0714 | O90: 0.9286 | Q90: 9 | R90: 2026 | S90: 46266
A91: Huixtla | C91: No Sindicalizados | E91: Septiembre | N91: 0.0714 | O91: 0.9286 | Q91: 9 | R91: 2026 | S91: 46266
A92: Huixtla | C92: Sindicalizados (Perm. Y Temp) | E92: Octubre | N92: 0.0767 | O92: 0.9233 | Q92: 10 | R92: 2026 | S92: 46296
A93: Huixtla | C93: No Sindicalizados | E93: Octubre | N93: 0.0767 | O93: 0.9233 | Q93: 10 | R93: 2026 | S93: 46296
... A97: Huixtla | C97: No Sindicalizados | E97: Diciembre | N97: 0.1106 | O97: 0.8894 | Q97: 12 | R97: 2026 | S97: 46357
A98: Modelo | B98: 112 | C98: No Sindicalizados | D98: 26 | E98: Enero | F98: 2912 | G98: 0 | H98: 0 | I98: 42 | J98: 0 | K98: 42 | L98: 0.014423077 | M98: 0.98557692 | N98: 0 | O98: 1 | P98: 0.014423077 | Q98: 1 | R98: 2023 | S98: 44927
A99: Modelo | B99: 112 | C99: No Sindicalizados | D99: 23 | E99: Febrero | F99: 2576 | G99: 0 | H99: 0 | I99: 48 | J99: 0 | K99: 48 | L99: 0.01863354 | M99: 0.98136646 | N99: 0 | O99: 1 | P99: 0.01863354 | Q99: 2 | R99: 2023 | S99: 44958
A100: Modelo | B100: 111 | C100: No Sindicalizados | D100: 26 | E100: Marzo | F100: 2886 | G100: 0 | H100: 0 | I100: 42 | J100: 12 | K100: 54 | L100: 0.018711019 | M100: 0.98128898 | N100: 0 | O100: 1 | P100: 0.018711019 | Q100: 3 | R100: 2023 | S100: 44986
A101: Modelo | B101: 111 | C101: No Sindicalizados | D101: 24 | E101: Abril | F101: 2664 | G101: 0 | H101: 0 | I101: 12 | J101: 24 | K101: 36 | L101: 0.013513514 | M101: 0.98648649 | N101: 0 | O101: 1 | P101: 0.013513514 | Q101: 4 | R101: 2023 | S101: 45017
A102: Modelo | B102: 111 | C102: No Sindicalizados | D102: 15 | E102: Mayo | F102: 1665 | G102: 0 | H102: 0 | I102: 5 | J102: 31 | K102: 36 | L102: 0.021621622 | M102: 0.97837838 | N102: 0 | O102: 1 | P102: 0.021621622 | Q102: 5 | R102: 2023 | S102: 45047
A103: Modelo | B103: 90 | C103: No Sindicalizados | D103: 22 | E103: Junio | F103: 1980 | G103: 0 | H103: 0 | I103: 6 | J103: 0 | K103: 6 | L103: 0.003030303 | M103: 0.9969697 | N103: 0 | O103: 1 | P103: 0.003030303 | Q103: 6 | R103: 2023 | S103: 45078
A104: Modelo | B104: 87 | C104: No Sindicalizados | D104: 21 | E104: Julio | F104: 1827 | G104: 0 | H104: 1 | I104: 0 | J104: 1 | K104: 2 | L104: 0.0010946907 | M104: 0.99890531 | N104: 0 | O104: 1 | P104: 0.0010946907 | Q104: 7 | R104: 2023 | S104: 45108
A105: Modelo | B105: 83 | C105: No Sindicalizados | D105: 23 | E105: Agosto | F105: 1909 | G105: 0 | H105: 0 | I105: 2 | J105: 0 | K105: 2 | L105: 0.0010476689 | M105: 0.99895233 | N105: 0 | O105: 1 | P105: 0.0010476689 | Q105: 8 | R105: 2023 | S105: 45139
A106: Modelo | B106: 86 | C106: No Sindicalizados | D106: 20 | E106: Septiembre | F106: 1720 | G106: 0 | H106: 0 | I106: 17 | J106: 31 | K106: 48 | L106: 0.027906977 | M106: 0.97209302 | N106: 0 | O106: 1 | P106: 0.027906977 | Q106: 9 | R106: 2023 | S106: 45170
A107: Modelo | B107: 92 | C107: No Sindicalizados | D107: 21 | E107: Octubre | F107: 1932 | G107: 0 | H107: 0 | I107: 0 | J107: 42 | K107: 42 | L107: 0.02173913 | M107: 0.97826087 | N107: 0 | O107: 1 | P107: 0.02173913 | Q107: 10 | R107: 2023 | S107: 45200
A108: Modelo | B108: 108 | C108: No Sindicalizados | D108: 23 | E108: Noviembre | F108: 2484 | G108: 0 | H108: 0 | I108: 46 | J108: 0 | K108: 46 | L108: 0.018518519 | M108: 0.98148148 | N108: 0 | O108: 1 | P108: 0.018518519 | Q108: 11 | R108: 2023 | S108: 45231
A109: Modelo | B109: 108 | C109: No Sindicalizados | D109: 25 | E109: Diciembre | F109: 2700 | G109: 0 | H109: 0 | I109: 2 | J109: 4 | K109: 6 | L109: 0.0022222222 | M109: 0.99777778 | N109: 0 | O109: 1 | P109: 0.0022222222 | Q109: 12 | R109: 2023 | S109: 45261
... A177: Modelo | B177: 135 | C177: No Sindicalizados | D177: 26 | E177: Abril | F177: 3510 | G177: 0 | H177: 0 | I177: 0 | J177: 0 | K177: 0 | L177: 0 | M177: 1 | N177: 0.0941 | O177: 0.9059 | P177: -0.0941 | Q177: 4 | R177: 2026 | S177: 46113
...

Sheet Analisis
B2: Suma de Plantilla | C2: Suma de Días laborables del mes | D2: Suma de Jornales | E2: Suma de FI | F2: Suma de PSG | G2: Suma de EG | H2: Suma de RT | I2: Suma de Ausencias | J2: Promedio de REAL AUSENT. | K2: Promedio de REAL COMPR. | L2: Promedio de PLAN | M2: Promedio de PLAN COMPR. | N2: Promedio de DIF +/- | P2: Año | Q2: Mes | R2: Promedio de REAL AUSENT. | T2: Etiquetas de fila | U2: Promedio de PLAN COMPR. | V2: Promedio de REAL COMPR. | X2: Etiquetas de fila | Y2: Promedio de REAL AUSENT. | AA2: Etiquetas de fila | AB2: Suma de FI | AC2: Suma de PSG | AD2: Suma de EG | AE2: Suma de RT | AG2: Etiquetas de fila | AH2: Suma de FI | AI2: Suma de PSG | AJ2: Suma de EG | AK2: Suma de RT
B3: 8644 | C3: 794 | D3: 214185 | E3: 12163 | F3: 1053 | G3: 2358 | H3: 1284 | I3: 16858 | J3: 0.056263603 | K3: 0.9437364 | L3: 0.09675 | M3: 0.90325 | N3: -0.042555147 | P3: 2023 | Q3: Enero | R3: 0.066848186 | T3: Enero | U3: 0.911275 | V3: 0.94393629 | X3: 2023 | Y3: 0.071835433 | AA3: 2026 | AB3: 12163 | AC3: 1053 | AD3: 2358 | AE3: 1284 | AG3: 2023 | AH3: 32144 | AI3: 2611 | AJ3: 5553 | AK3: 2475
P4: 2023 | Q4: Febrero | R4: 0.062747301 | T4: Febrero | U4: 0.8928 | V4: 0.94710658 | X4: 2024 | Y4: 0.059150591 | AA4: Total general | AB4: 12163 | AC4: 1053 | AD4: 2358 | AE4: 1284 | AG4: 2024 | AH4: 26402 | AI4: 2605 | AJ4: 4970 | AK4: 2336
P5: 2023 | Q5: Marzo | R5: 0.063848824 | T5: Marzo | U5: 0.9057 | V5: 0.93947536 | X5: 2025 | Y5: 0.056116444 | AG5: 2025 | AH5: 27408 | AI5: 2244 | AJ5: 5217 | AK5: 2125
P6: 2023 | Q6: Abril | R6: 0.072175805 | T6: Abril | U6: 0.89495 | V6: 0.94442736 | X6: 2026 | Y6: 0.056263603 | AG6: 2026 | AH6: 12163 | AI6: 1053 | AJ6: 2358 | AK6: 1284
P7: 2023 | Q7: Mayo | R7: 0.073010612 | T7: Mayo | U7: 0.89695 | X7: Total general | Y7: 0.061757101 | AG7: Total general | AH7: 98117 | AI7: 8513 | AJ7: 18098 | AK7: 8220
P8: 2023 | Q8: Junio | R8: 0.11635832 | T8: Junio | U8: 0.87885
P9: 2023 | Q9: Julio | R9: 0.075294049 | T9: Julio | U9: 0.888975
P10: 2023 | Q10: Agosto | R10: 0.066134467 | T10: Agosto | U10: 0.900525
P11: 2023 | Q11: Septiembre | R11: 0.062478195 | T11: Septiembre | U11: 0.92135
P12: 2023 | Q12: Octubre | R12: 0.064532126 | T12: Octubre | U12: 0.931275
P13: 2023 | Q13: Noviembre | R13: 0.083703052 | T13: Noviembre | U13: 0.915525
P14: 2023 | Q14: Diciembre | R14: 0.054894259 | T14: Diciembre | U14: 0.900825
P15: Total 2023 | R15: 0.071835433 | T15: Total general | U15: 0.90325 | V15: 0.9437364
P16: 2024 | Q16: Enero | R16: 0.048372214
P17: 2024 | Q17: Febrero | R17: 0.050935901
P18: 2024 | Q18: Marzo | R18: 0.055534346
P19: 2024 | Q19: Abril | R19: 0.065905943
P20: 2024 | Q20: Mayo | R20: 0.086882738
P21: 2024 | Q21: Junio | R21: 0.079717764
P22: 2024 | Q22: Julio | R22: 0.061689782
P23: 2024 | Q23: Agosto | R23: 0.055183528
P24: 2024 | Q24: Septiembre | R24: 0.049326515
P25: 2024 | Q25: Octubre | R25: 0.052723713
P26: 2024 | Q26: Noviembre | R26: 0.05228066
P27: 2024 | Q27: Diciembre | R27: 0.051253992
P28: Total 2024 | R28: 0.059150591
P29: 2025 | Q29: Enero | R29: 0.049524622
P30: 2025 | Q30: Febrero | R30: 0.060256053
P31: 2025 | Q31: Marzo | R31: 0.052095489
P32: 2025 | Q32: Abril | R32: 0.058896704
P33: 2025 | Q33: Mayo | R33: 0.060983995
P34: 2025 | Q34: Junio | R34: 0.075063892
P35: 2025 | Q35: Julio | R35: 0.068833513
P36: 2025 | Q36: Agosto | R36: 0.058398281
P37: 2025 | Q37: Septiembre | R37: 0.044790409
P38: 2025 | Q38: Octubre | R38: 0.038944314
P39: 2025 | Q39: Noviembre | R39: 0.048813035
P40: 2025 | Q40: Diciembre | R40: 0.05679702
P41: Total 2025 | R41: 0.056116444
...

Sheet Info
C2: Suma de Plantilla | D2: Suma de Días laborables | E2: Suma de Jornales | F2: FI | G2: PSG | H2: EG | I2: RT | J2: Suma de Ausencias | K2: Promedio de REAL AUSENT. | L2: Promedio de REAL COMPR. | M2: Suma de PLAN AUSENT. | N2: Promedio de PLAN COMPR. | O2: Promedio de DIF +/-
C3: =GETPIVOTDATA("Suma de Plantilla",Analisis!$B$2) -> 8644 | D3: =GETPIVOTDATA("Suma de Días laborables del mes",Analisis!$B$2) -> 794 | E3: =GETPIVOTDATA("Suma de Jornales",Analisis!$B$2) -> 214185 | F3: =GETPIVOTDATA("Suma de FI",Analisis!$B$2) -> 12163 | G3: =GETPIVOTDATA("Suma de PSG",Analisis!$B$2) -> 1053 | H3: =GETPIVOTDATA("Suma de EG",Analisis!$B$2) -> 2358 | I3: =GETPIVOTDATA("Suma de RT",Analisis!$B$2) -> 1284 | J3: =GETPIVOTDATA("Suma de Ausencias",Analisis!$B$2) -> 16858 | K3: =IFERROR(GETPIVOTDATA("Promedio de REAL AUSENT.",Analisis!$B$2),0) -> 0.056263603 | L3: =IFERROR(GETPIVOTDATA("Promedio de REAL COMPR.",Analisis!$B$2),0) -> 0.9437364 | M3: =IFERROR(GETPIVOTDATA("Suma de PLAN AUSENT.",Analisis!$B$2),0) -> 0 | N3: =IFERROR(GETPIVOTDATA("Promedio de PLAN COMPR.",Analisis!$B$2),0) -> 0.90325 | O3: =IFERROR(GETPIVOTDATA("Promedio de DIF +/-",Analisis!$B$2),0) -> -0.042555147
C5: Enero | D5: Febrero | E5: Marzo | F5: Abril | G5: Mayo | H5: Junio | I5: Julio | J5: Agosto | K5: Septiembre | L5: Octubre | M5: Noviembre | N5: Diciembre
B6: 2023 | C6: =IFERROR(AVERAGEIFS(Analisis!$R:$R,Analisis!$Q:$Q,Info!C$5,Analisis!$P:$P,Info!$B6),0) -> 0.066848186 | D6: =IFERROR(AVERAGEIFS(Analisis!$R:$R,Analisis!$Q:$Q,Info!D$5,Analisis!$P:$P,Info!$B6),0) -> 0.062747301 | E6: =IFERROR(AVERAGEIFS(Analisis!$R:$R,Analisis!$Q:$Q,Info!E$5,Analisis!$P:$P,Info!$B6),0) -> 0.063848824 | F6: =IFERROR(AVERAGEIFS(Analisis!$R:$R,Analisis!$Q:$Q,Info!F$5,Analisis!$P:$P,Info!$B6),0) -> 0.072175805 | G6: =IFERROR(AVERAGEIFS(Analisis!$R:$R,Analisis!$Q:$Q,Info!G$5,Analisis!$P:$P,Info!$B6),0) -> 0.073010612 | H6: =IFERROR(AVERAGEIFS(Analisis!$R:$R,Analisis!$Q:$Q,Info!H$5,Analisis!$P:$P,Info!$B6),0) -> 0.11635832 | I6: =IFERROR(AVERAGEIFS(Analisis!$R:$R,Analisis!$Q:$Q,Info!I$5,Analisis!$P:$P,Info!$B6),0) -> 0.075294049 | J6: =IFERROR(AVERAGEIFS(Analisis!$R:$R,Analisis!$Q:$Q,Info!J$5,Analisis!$P:$P,Info!$B6),0) -> 0.066134467 | ... N6: =IFERROR(AVERAGEIFS(Analisis!$R:$R,Analisis!$Q:$Q,Info!N$5,Analisis!$P:$P,Info!$B6),0) -> 0.054894259
B7: 2024 | C7: =IFERROR(AVERAGEIFS(Analisis!$R:$R,Analisis!$Q:$Q,Info!C$5,Analisis!$P:$P,Info!$B7),0) -> 0.048372214 | D7: =IFERROR(AVERAGEIFS(Analisis!$R:$R,Analisis!$Q:$Q,Info!D$5,Analisis!$P:$P,Info!$B7),0) -> 0.050935901 | E7: =IFERROR(AVERAGEIFS(Analisis!$R:$R,Analisis!$Q:$Q,Info!E$5,Analisis!$P:$P,Info!$B7),0) -> 0.055534346 | F7: =IFERROR(AVERAGEIFS(Analisis!$R:$R,Analisis!$Q:$Q,Info!F$5,Analisis!$P:$P,Info!$B7),0) -> 0.065905943 | G7: =IFERROR(AVERAGEIFS(Analisis!$R:$R,Analisis!$Q:$Q,Info!G$5,Analisis!$P:$P,Info!$B7),0) -> 0.086882738 | H7: =IFERROR(AVERAGEIFS(Analisis!$R:$R,Analisis!$Q:$Q,Info!H$5,Analisis!$P:$P,Info!$B7),0) -> 0.079717764 | I7: =IFERROR(AVERAGEIFS(Analisis!$R:$R,Analisis!$Q:$Q,Info!I$5,Analisis!$P:$P,Info!$B7),0) -> 0.061689782 | J7: =IFERROR(AVERAGEIFS(Analisis!$R:$R,Analisis!$Q:$Q,Info!J$5,Analisis!$P:$P,Info!$B7),0) -> 0.055183528 | ... N7: =IFERROR(AVERAGEIFS(Analisis!$R:$R,Analisis!$Q:$Q,Info!N$5,Analisis!$P:$P,Info!$B7),0) -> 0.051253992
B8: 2025 | C8: =IFERROR(AVERAGEIFS(Analisis!$R:$R,Analisis!$Q:$Q,Info!C$5,Analisis!$P:$P,Info!$B8),0) -> 0.049524622 | D8: =IFERROR(AVERAGEIFS(Analisis!$R:$R,Analisis!$Q:$Q,Info!D$5,Analisis!$P:$P,Info!$B8),0) -> 0.060256053 | E8: =IFERROR(AVERAGEIFS(Analisis!$R:$R,Analisis!$Q:$Q,Info!E$5,Analisis!$P:$P,Info!$B8),0) -> 0.052095489 | F8: =IFERROR(AVERAGEIFS(Analisis!$R:$R,Analisis!$Q:$Q,Info!F$5,Analisis!$P:$P,Info!$B8),0) -> 0.058896704 | G8: =IFERROR(AVERAGEIFS(Analisis!$R:$R,Analisis!$Q:$Q,Info!G$5,Analisis!$P:$P,Info!$B8),0) -> 0.060983995 | H8: =IFERROR(AVERAGEIFS(Analisis!$R:$R,Analisis!$Q:$Q,Info!H$5,Analisis!$P:$P,Info!$B8),0) -> 0.075063892 | I8: =IFERROR(AVERAGEIFS(Analisis!$R:$R,Analisis!$Q:$Q,Info!I$5,Analisis!$P:$P,Info!$B8),0) -> 0.068833513 | J8: =IFERROR(AVERAGEIFS(Analisis!$R:$R,Analisis!$Q:$Q,Info!J$5,Analisis!$P:$P,Info!$B8),0) -> 0.058398281 | ... N8: =IFERROR(AVERAGEIFS(Analisis!$R:$R,Analisis!$Q:$Q,Info!N$5,Analisis!$P:$P,Info!$B8),0) -> 0.05679702
B9: 2026 | C9: =IFERROR(AVERAGEIFS(Analisis!$R:$R,Analisis!$Q:$Q,Info!C$5,Analisis!$P:$P,Info!$B9),0) -> 0.056063711 | D9: =IFERROR(AVERAGEIFS(Analisis!$R:$R,Analisis!$Q:$Q,Info!D$5,Analisis!$P:$P,Info!$B9),0) -> 0.052893416 | E9: =IFERROR(AVERAGEIFS(Analisis!$R:$R,Analisis!$Q:$Q,Info!E$5,Analisis!$P:$P,Info!$B9),0) -> 0.060524644 | F9: =IFERROR(AVERAGEIFS(Analisis!$R:$R,Analisis!$Q:$Q,Info!F$5,Analisis!$P:$P,Info!$B9),0) -> 0.055572641 | G9: =IFERROR(AVERAGEIFS(Analisis!$R:$R,Analisis!$Q:$Q,Info!G$5,Analisis!$P:$P,Info!$B9),0) -> 0 | H9: =IFERROR(AVERAGEIFS(Analisis!$R:$R,Analisis!$Q:$Q,Info!H$5,Analisis!$P:$P,Info!$B9),0) -> 0 | I9: =IFERROR(AVERAGEIFS(Analisis!$R:$R,Analisis!$Q:$Q,Info!I$5,Analisis!$P:$P,Info!$B9),0) -> 0 | J9: =IFERROR(AVERAGEIFS(Analisis!$R:$R,Analisis!$Q:$Q,Info!J$5,Analisis!$P:$P,Info!$B9),0) -> 0 | ... N9: =IFERROR(AVERAGEIFS(Analisis!$R:$R,Analisis!$Q:$Q,Info!N$5,Analisis!$P:$P,Info!$B9),0) -> 0
C11: PLAN COMPR. | D11: REAL COMPR.
B12: Enero | C12: =IFERROR(AVERAGEIFS(Analisis!$U:$U,Analisis!$T:$T,Info!$B12),0) -> 0.911275 | D12: =IFERROR(AVERAGEIFS(Analisis!$V:$V,Analisis!$T:$T,Info!$B12),0) -> 0.94393629
B13: Febrero | C13: =IFERROR(AVERAGEIFS(Analisis!$U:$U,Analisis!$T:$T,Info!$B13),0) -> 0.8928 | D13: =IFERROR(AVERAGEIFS(Analisis!$V:$V,Analisis!$T:$T,Info!$B13),0) -> 0.94710658
B14: Marzo | C14: =IFERROR(AVERAGEIFS(Analisis!$U:$U,Analisis!$T:$T,Info!$B14),0) -> 0.9057 | D14: =IFERROR(AVERAGEIFS(Analisis!$V:$V,Analisis!$T:$T,Info!$B14),0) -> 0.93947536
B15: Abril | C15: =IFERROR(AVERAGEIFS(Analisis!$U:$U,Analisis!$T:$T,Info!$B15),0) -> 0.89495 | D15: =IFERROR(AVERAGEIFS(Analisis!$V:$V,Analisis!$T:$T,Info!$B15),0) -> 0.94442736
B16: Mayo | C16: =IFERROR(AVERAGEIFS(Analisis!$U:$U,Analisis!$T:$T,Info!$B16),0) -> 0.89695 | D16: =IFERROR(AVERAGEIFS(Analisis!$V:$V,Analisis!$T:$T,Info!$B16),0) -> 0
B17: Junio | C17: =IFERROR(AVERAGEIFS(Analisis!$U:$U,Analisis!$T:$T,Info!$B17),0) -> 0.87885 | D17: =IFERROR(AVERAGEIFS(Analisis!$V:$V,Analisis!$T:$T,Info!$B17),0) -> 0
B18: Julio | C18: =IFERROR(AVERAGEIFS(Analisis!$U:$U,Analisis!$T:$T,Info!$B18),0) -> 0.888975 | D18: =IFERROR(AVERAGEIFS(Analisis!$V:$V,Analisis!$T:$T,Info!$B18),0) -> 0
B19: Agosto | C19: =IFERROR(AVERAGEIFS(Analisis!$U:$U,Analisis!$T:$T,Info!$B19),0) -> 0.900525 | D19: =IFERROR(AVERAGEIFS(Analisis!$V:$V,Analisis!$T:$T,Info!$B19),0) -> 0
B20: Septiembre | C20: =IFERROR(AVERAGEIFS(Analisis!$U:$U,Analisis!$T:$T,Info!$B20),0) -> 0.92135 | D20: =IFERROR(AVERAGEIFS(Analisis!$V:$V,Analisis!$T:$T,Info!$B20),0) -> 0
B21: Octubre | C21: =IFERROR(AVERAGEIFS(Analisis!$U:$U,Analisis!$T:$T,Info!$B21),0) -> 0.931275 | D21: =IFERROR(AVERAGEIFS(Analisis!$V:$V,Analisis!$T:$T,Info!$B21),0) -> 0
B22: Noviembre | C22: =IFERROR(AVERAGEIFS(Analisis!$U:$U,Analisis!$T:$T,Info!$B22),0) -> 0.915525 | D22: =IFERROR(AVERAGEIFS(Analisis!$V:$V,Analisis!$T:$T,Info!$B22),0) -> 0
B23: Diciembre | C23: =IFERROR(AVERAGEIFS(Analisis!$U:$U,Analisis!$T:$T,Info!$B23),0) -> 0.900825 | D23: =IFERROR(AVERAGEIFS(Analisis!$V:$V,Analisis!$T:$T,Info!$B23),0) -> 0
C25: FI | D25: PSG | E25: EG | F25: RT
B26: 2023 | C26: =IFERROR(AVERAGEIFS(Analisis!AB:AB,Analisis!$AA:$AA,Info!$B26),0) -> 0 | D26: =IFERROR(AVERAGEIFS(Analisis!AC:AC,Analisis!$AA:$AA,Info!$B26),0) -> 0 | E26: =IFERROR(AVERAGEIFS(Analisis!AD:AD,Analisis!$AA:$AA,Info!$B26),0) -> 0 | F26: =IFERROR(AVERAGEIFS(Analisis!AE:AE,Analisis!$AA:$AA,Info!$B26),0) -> 0
B27: 2024 | C27: =IFERROR(AVERAGEIFS(Analisis!AB:AB,Analisis!$AA:$AA,Info!$B27),0) -> 0 | D27: =IFERROR(AVERAGEIFS(Analisis!AC:AC,Analisis!$AA:$AA,Info!$B27),0) -> 0 | E27: =IFERROR(AVERAGEIFS(Analisis!AD:AD,Analisis!$AA:$AA,Info!$B27),0) -> 0 | F27: =IFERROR(AVERAGEIFS(Analisis!AE:AE,Analisis!$AA:$AA,Info!$B27),0) -> 0
B28: 2025 | C28: =IFERROR(AVERAGEIFS(Analisis!AB:AB,Analisis!$AA:$AA,Info!$B28),0) -> 0 | D28: =IFERROR(AVERAGEIFS(Analisis!AC:AC,Analisis!$AA:$AA,Info!$B28),0) -> 0 | E28: =IFERROR(AVERAGEIFS(Analisis!AD:AD,Analisis!$AA:$AA,Info!$B28),0) -> 0 | F28: =IFERROR(AVERAGEIFS(Analisis!AE:AE,Analisis!$AA:$AA,Info!$B28),0) -> 0
B29: 2026 | C29: =IFERROR(AVERAGEIFS(Analisis!AB:AB,Analisis!$AA:$AA,Info!$B29),0) -> 12163 | D29: =IFERROR(AVERAGEIFS(Analisis!AC:AC,Analisis!$AA:$AA,Info!$B29),0) -> 1053 | E29: =IFERROR(AVERAGEIFS(Analisis!AD:AD,Analisis!$AA:$AA,Info!$B29),0) -> 2358 | F29: =IFERROR(AVERAGEIFS(Analisis!AE:AE,Analisis!$AA:$AA,Info!$B29),0) -> 1284
C31: REAL AUSENT
B32: 2023 | C32: =IFERROR(AVERAGEIFS(Analisis!$Y:$Y,Analisis!$X:$X,Info!$B32),0) -> 0.071835433
B33: 2024 | C33: =IFERROR(AVERAGEIFS(Analisis!$Y:$Y,Analisis!$X:$X,Info!$B33),0) -> 0.059150591
B34: 2025 | C34: =IFERROR(AVERAGEIFS(Analisis!$Y:$Y,Analisis!$X:$X,Info!$B34),0) -> 0.056116444
B35: 2026 | C35: =IFERROR(AVERAGEIFS(Analisis!$Y:$Y,Analisis!$X:$X,Info!$B35),0) -> 0.056263603
C37: FI | D37: PSG | E37: EG | F37: RT
B38: 2023 | C38: =IFERROR(AVERAGEIFS(Analisis!AH:AH,Analisis!$AG:$AG,Info!$B38),0) -> 32144 | D38: =IFERROR(AVERAGEIFS(Analisis!AI:AI,Analisis!$AG:$AG,Info!$B38),0) -> 2611 | E38: =IFERROR(AVERAGEIFS(Analisis!AJ:AJ,Analisis!$AG:$AG,Info!$B38),0) -> 5553 | F38: =IFERROR(AVERAGEIFS(Analisis!AK:AK,Analisis!$AG:$AG,Info!$B38),0) -> 2475
B39: 2024 | C39: =IFERROR(AVERAGEIFS(Analisis!AH:AH,Analisis!$AG:$AG,Info!$B39),0) -> 26402 | D39: =IFERROR(AVERAGEIFS(Analisis!AI:AI,Analisis!$AG:$AG,Info!$B39),0) -> 2605 | E39: =IFERROR(AVERAGEIFS(Analisis!AJ:AJ,Analisis!$AG:$AG,Info!$B39),0) -> 4970 | F39: =IFERROR(AVERAGEIFS(Analisis!AK:AK,Analisis!$AG:$AG,Info!$B39),0) -> 2336
B40: 2025 | C40: =IFERROR(AVERAGEIFS(Analisis!AH:AH,Analisis!$AG:$AG,Info!$B40),0) -> 27408 | D40: =IFERROR(AVERAGEIFS(Analisis!AI:AI,Analisis!$AG:$AG,Info!$B40),0) -> 2244 | E40: =IFERROR(AVERAGEIFS(Analisis!AJ:AJ,Analisis!$AG:$AG,Info!$B40),0) -> 5217 | F40: =IFERROR(AVERAGEIFS(Analisis!AK:AK,Analisis!$AG:$AG,Info!$B40),0) -> 2125
B41: 2026 | C41: =IFERROR(AVERAGEIFS(Analisis!AH:AH,Analisis!$AG:$AG,Info!$B41),0) -> 12163 | D41: =IFERROR(AVERAGEIFS(Analisis!AI:AI,Analisis!$AG:$AG,Info!$B41),0) -> 1053 | E41: =IFERROR(AVERAGEIFS(Analisis!AJ:AJ,Analisis!$AG:$AG,Info!$B41),0) -> 2358 | F41: =IFERROR(AVERAGEIFS(Analisis!AK:AK,Analisis!$AG:$AG,Info!$B41),0) -> 1284

Sheet DashBoard
